Workbook

Sheet Fig7e
A1: Front and rear data of MDCK C3 sample A
B2: Averaged |y| displacement [μm]
A3: Time [h] | B3: Front | C3: Rear
A4: 0 | B4: 0 | C4: 0
A5: 0.25 | B5: 1.0463822 | C5: 1
A6: 0.5 | B6: 2.2556391 | C6: 0.03538175
A7: 0.75 | B7: 1.7573529 | C7: 0.87269373
A8: 1 | B8: 0.21543986 | C8: 2.2383721
A9: 1.25 | B9: 6.0729367 | C9: 3
A10: 1.5 | B10: 4.9980916 | C10: 4.463138
A11: 1.75 | B11: 7.5687023 | C11: 1.7059891
A12: 2 | B12: 9.8394834 | C12: 4.7428571
A13: 2.25 | B13: 12.925859 | C13: 4.3776091
A14: 2.5 | B14: 14.694683 | C14: 6.4302103
A15: 2.75 | B15: 19.821154 | C15: 10.9
... A44: 10 | B44: 100.27963 | C44: 52.857671

Sheet Fig7f
A1: Front, rear and spreading data of MDCK C3 averaged over samples A-G
B2: Averaged |y| displacement [μm]
A3: Time [h] | B3: Front | C3: Rear | D3: Spreading
A4: 0 | B4: 0 | C4: 0 | D4: 0
A5: 0.25 | B5: 3.7290445 | C5: 2.4622387 | D5: 1.2668058
A6: 0.5 | B6: 6.4026711 | C6: 5.0942133 | D6: 1.3084577
A7: 0.75 | B7: 8.7525669 | C7: 7.6614436 | D7: 1.0911234
A8: 1 | B8: 11.26647 | C8: 8.6082702 | D8: 2.6581995
A9: 1.25 | B9: 14.145164 | C9: 11.139109 | D9: 3.0060543
A10: 1.5 | B10: 16.219031 | C10: 13.544414 | D10: 2.6746176
A11: 1.75 | B11: 19.161381 | C11: 15.816616 | D11: 3.3447645
A12: 2 | B12: 23.147485 | C12: 17.911034 | D12: 5.236451
A13: 2.25 | B13: 27.686176 | C13: 20.709699 | D13: 6.9764777
A14: 2.5 | B14: 30.537874 | C14: 22.936369 | D14: 7.6015046
A15: 2.75 | B15: 34.630943 | C15: 25.396264 | D15: 9.234679
... A44: 10 | B44: 142.33833 | C44: 112.58671 | D44: 29.751623

Sheet FigS2a
A1: Front and rear data of MDCK C3 sample A
B2: Averaged |y| displacement [μm]
A3: Time [h] | B3: Front | C3: Rear
A4: 0 | B4: 0 | C4: 0
A5: 0.25 | B5: 1.0463822 | C5: 1
A6: 0.5 | B6: 2.2556391 | C6: 0.03538175
A7: 0.75 | B7: 1.7573529 | C7: 0.87269373
A8: 1 | B8: 0.21543986 | C8: 2.2383721
A9: 1.25 | B9: 6.0729367 | C9: 3
A10: 1.5 | B10: 4.9980916 | C10: 4.463138
A11: 1.75 | B11: 7.5687023 | C11: 1.7059891
A12: 2 | B12: 9.8394834 | C12: 4.7428571
A13: 2.25 | B13: 12.925859 | C13: 4.3776091
A14: 2.5 | B14: 14.694683 | C14: 6.4302103
A15: 2.75 | B15: 19.821154 | C15: 10.9
... A44: 10 | B44: 100.27963 | C44: 52.857671

Sheet FigS2b
A1: Front and rear data of MDCK C3 sample B
B2: Averaged |y| displacement [μm]
A3: Time [h] | B3: Front | C3: Rear
A4: 0 | B4: 0 | C4: 0
A5: 0.25 | B5: 1.0051724 | C5: 4.4822934
A6: 0.5 | B6: 1.9187817 | C6: 9.616041
A7: 0.75 | B7: 3.9608177 | C7: 15.948805
A8: 1 | B8: 4.8771331 | C8: 16.183219
A9: 1.25 | B9: 5.7231544 | C9: 16.388889
A10: 1.5 | B10: 6.7576271 | C10: 16.755973
A11: 1.75 | B11: 7.8260135 | C11: 17.025818
A12: 2 | B12: 9.0503356 | C12: 17.367003
A13: 2.25 | B13: 10.624138 | C13: 17.875421
A14: 2.5 | B14: 11.87585 | C14: 17.975945
A15: 2.75 | B15: 13.451613 | C15: 18.618151
... A44: 10 | B44: 83.94898 | C44: 163.30479

Sheet FigS2c
A1: Front and rear data of MDCK C3 sample C
B2: Averaged |y| displacement [μm]
A3: Time [h] | B3: Front | C3: Rear
A4: 0 | B4: 0 | C4: 0
A5: 0.25 | B5: 0.58633094 | C5: 0.63372093
A6: 0.5 | B6: 0.99299475 | C6: 2.9375
A7: 0.75 | B7: 0.23302752 | C7: 4.1683367
A8: 1 | B8: 4.336163 | C8: 4.397351
A9: 1.25 | B9: 3.5976027 | C9: 5.5502183
A10: 1.5 | B10: 5.6805324 | C10: 7.1327623
A11: 1.75 | B11: 7.8020134 | C11: 13.95354
A12: 2 | B12: 10.553415 | C12: 12.926
A13: 2.25 | B13: 14.84456 | C13: 14.605749
A14: 2.5 | B14: 11.380454 | C14: 17.040307
A15: 2.75 | B15: 13.786116 | C15: 18.193684
... A44: 10 | B44: 90.922942 | C44: 77.946392

Sheet FigS2d
A4: Front and rear data of MDCK C3 sample D
B5: Averaged |y| displacement [μm]
A6: Time [h] | B6: Front | C6: Rear
A7: 0 | B7: 0 | C7: 0
A8: 0.25 | B8: 5.5064695 | C8: 2.1409002
A9: 0.5 | B9: 6.6927273 | C9: 4.2224371
A10: 0.75 | B10: 8.2640145 | C10: 6.1589147
A11: 1 | B11: 8.4343972 | C11: 7.4193548
A12: 1.25 | B12: 8.6316726 | C12: 13.013208
A13: 1.5 | B13: 9.5376147 | C13: 13.561224
A14: 1.75 | B14: 12.633028 | C14: 15.030476
A15: 2 | B15: 14.360294 | C15: 15.251938
A16: 2.25 | B16: 17.89414 | C16: 18.474609
A17: 2.5 | B17: 22.364991 | C17: 19.678846
A18: 2.75 | B18: 23.982922 | C18: 22.713761
... A47: 10 | B47: 136.47491 | C47: 128.12383

Sheet FigS2e
A1: Front and rear data of MDCK C3 sample E
B2: Averaged |y| displacement [μm]
A3: Time [h] | B3: Front | C3: Rear
A4: 0 | B4: 0 | C4: 0
A5: 0.25 | B5: 7.5807623 | C5: 1.6618705
A6: 0.5 | B6: 13.448454 | C6: 4.6872659
A7: 0.75 | B7: 17.920071 | C7: 5.1097804
A8: 1 | B8: 22.613139 | C8: 0.71619048
A9: 1.25 | B9: 26.585911 | C9: 2.1205674
A10: 1.5 | B10: 27.825312 | C10: 4.8853974
A11: 1.75 | B11: 27.55036 | C11: 4.4945652
A12: 2 | B12: 30.913824 | C12: 4.9168207
A13: 2.25 | B13: 32.478114 | C13: 5.4463602
A14: 2.5 | B14: 36.506849 | C14: 7.4572491
A15: 2.75 | B15: 41.467687 | C15: 7.2640145
... A44: 10 | B44: 219.65664 | C44: 38.155039

Sheet FigS2f
A1: Front and rear data of MDCK C3 sample F
B2: Averaged |y| displacement [μm]
A3: Time [h] | B3: Front | C3: Rear
A4: 0 | B4: 0 | C4: 0
A5: 0.25 | B5: 6.6064736 | C5: 2.0017241
A6: 0.5 | B6: 12.282828 | C6: 3.6103448
A7: 0.75 | B7: 18.018739 | C7: 5.4741379
A8: 1 | B8: 23.313131 | C8: 7.2982759
A9: 1.25 | B9: 28.574074 | C9: 8.9741379
A10: 1.5 | B10: 34.428814 | C10: 10.948276
A11: 1.75 | B11: 41.810256 | C11: 12.724138
A12: 2 | B12: 53.027165 | C12: 14.581315
A13: 2.25 | B13: 64.136594 | C13: 17.182906
A14: 2.5 | B14: 67.037607 | C14: 20.436742
A15: 2.75 | B15: 71.572635 | C15: 23.324653
... A44: 10 | B44: 152.63283 | C44: 136.74486

Sheet FigS2g
A1: Front and rear data of MDCK C3 sample G
B2: Averaged |y| displacement [μm]
A3: Time [h] | B3: Front | C3: Rear
A4: 0 | B4: 0 | C4: 0
A5: 0.25 | B5: 3.7717206 | C5: 5.3151618
A6: 0.5 | B6: 7.2272727 | C6: 10.550523
A7: 0.75 | B7: 11.113946 | C7: 15.897436
A8: 1 | B8: 15.075885 | C8: 22.005128
A9: 1.25 | B9: 19.830795 | C9: 28.926746
A10: 1.5 | B10: 24.305228 | C10: 37.064125
A11: 1.75 | B11: 28.939292 | C11: 45.781787
A12: 2 | B12: 34.287879 | C12: 55.591304
A13: 2.25 | B13: 40.89983 | C13: 67.005236
A14: 2.5 | B14: 49.904682 | C14: 71.535284
A15: 2.75 | B15: 58.334471 | C15: 76.759582
... A44: 10 | B44: 212.45238 | C44: 190.97436

Sheet FigS2h
A1: Front data of MDCK C3 samples A-G
B2: Front Averaged |y| displacement [μm]
A3: Time [h] | B3: Mean | C3: Sample A | D3: Sample B | E3: Sample C | F3: Sample D | G3: Sample E | H3: Sample F | I3: Sample G
A4: 0 | B4: 0 | C4: 0 | D4: 0 | E4: 0 | F4: 0 | G4: 0 | H4: 0 | I4: 0
A5: 0.25 | B5: 3.7290445 | C5: 1.0463822 | D5: 1.0051724 | E5: 0.58633094 | F5: 5.5064695 | G5: 7.5807623 | H5: 6.6064736 | I5: 3.7717206
A6: 0.5 | B6: 6.4026711 | C6: 2.2556391 | D6: 1.9187817 | E6: 0.99299475 | F6: 6.6927273 | G6: 13.448454 | H6: 12.282828 | I6: 7.2272727
A7: 0.75 | B7: 8.7525669 | C7: 1.7573529 | D7: 3.9608177 | E7: 0.23302752 | F7: 8.2640145 | G7: 17.920071 | H7: 18.018739 | I7: 11.113946
A8: 1 | B8: 11.26647 | C8: 0.21543986 | D8: 4.8771331 | E8: 4.336163 | F8: 8.4343972 | G8: 22.613139 | H8: 23.313131 | I8: 15.075885
A9: 1.25 | B9: 14.145164 | C9: 6.0729367 | D9: 5.7231544 | E9: 3.5976027 | F9: 8.6316726 | G9: 26.585911 | H9: 28.574074 | I9: 19.830795
A10: 1.5 | B10: 16.219031 | C10: 4.9980916 | D10: 6.7576271 | E10: 5.6805324 | F10: 9.5376147 | G10: 27.825312 | H10: 34.428814 | I10: 24.305228
A11: 1.75 | B11: 19.161381 | C11: 7.5687023 | D11: 7.8260135 | E11: 7.8020134 | F11: 12.633028 | G11: 27.55036 | H11: 41.810256 | I11: 28.939292
A12: 2 | B12: 23.147485 | C12: 9.8394834 | D12: 9.0503356 | E12: 10.553415 | F12: 14.360294 | G12: 30.913824 | H12: 53.027165 | I12: 34.287879
A13: 2.25 | B13: 27.686176 | C13: 12.925859 | D13: 10.624138 | E13: 14.84456 | F13: 17.89414 | G13: 32.478114 | H13: 64.136594 | I13: 40.89983
A14: 2.5 | B14: 30.537874 | C14: 14.694683 | D14: 11.87585 | E14: 11.380454 | F14: 22.364991 | G14: 36.506849 | H14: 67.037607 | I14: 49.904682
A15: 2.75 | B15: 34.630943 | C15: 19.821154 | D15: 13.451613 | E15: 13.786116 | F15: 23.982922 | G15: 41.467687 | H15: 71.572635 | I15: 58.334471
... A44: 10 | B44: 142.33833 | C44: 100.27963 | D44: 83.94898 | E44: 90.922942 | F44: 136.47491 | G44: 219.65664 | H44: 152.63283 | I44: 212.45238

Sheet FigS2i
A1: Rear data of MDCK C3 samples A-G
B2: Rear Averaged |y| displacement [μm]
A3: Time [h] | B3: Mean | C3: Sample A | D3: Sample B | E3: Sample C | F3: Sample D | G3: Sample E | H3: Sample F | I3: Sample G
A4: 0 | B4: 0 | C4: 0 | D4: 0 | E4: 0 | F4: 0 | G4: 0 | H4: 0 | I4: 0
A5: 0.25 | B5: 2.4622387 | C5: 1 | D5: 4.4822934 | E5: 0.63372093 | F5: 2.1409002 | G5: 1.6618705 | H5: 2.0017241 | I5: 5.3151618
A6: 0.5 | B6: 5.0942133 | C6: 0.03538175 | D6: 9.616041 | E6: 2.9375 | F6: 4.2224371 | G6: 4.6872659 | H6: 3.6103448 | I6: 10.550523
A7: 0.75 | B7: 7.6614436 | C7: 0.87269373 | D7: 15.948805 | E7: 4.1683367 | F7: 6.1589147 | G7: 5.1097804 | H7: 5.4741379 | I7: 15.897436
A8: 1 | B8: 8.6082702 | C8: 2.2383721 | D8: 16.183219 | E8: 4.397351 | F8: 7.4193548 | G8: 0.71619048 | H8: 7.2982759 | I8: 22.005128
A9: 1.25 | B9: 11.139109 | C9: 3 | D9: 16.388889 | E9: 5.5502183 | F9: 13.013208 | G9: 2.1205674 | H9: 8.9741379 | I9: 28.926746
A10: 1.5 | B10: 13.544414 | C10: 4.463138 | D10: 16.755973 | E10: 7.1327623 | F10: 13.561224 | G10: 4.8853974 | H10: 10.948276 | I10: 37.064125
A11: 1.75 | B11: 15.816616 | C11: 1.7059891 | D11: 17.025818 | E11: 13.95354 | F11: 15.030476 | G11: 4.4945652 | H11: 12.724138 | I11: 45.781787
A12: 2 | B12: 17.911034 | C12: 4.7428571 | D12: 17.367003 | E12: 12.926 | F12: 15.251938 | G12: 4.9168207 | H12: 14.581315 | I12: 55.591304
A13: 2.25 | B13: 20.709699 | C13: 4.3776091 | D13: 17.875421 | E13: 14.605749 | F13: 18.474609 | G13: 5.4463602 | H13: 17.182906 | I13: 67.005236
A14: 2.5 | B14: 22.936369 | C14: 6.4302103 | D14: 17.975945 | E14: 17.040307 | F14: 19.678846 | G14: 7.4572491 | H14: 20.436742 | I14: 71.535284
A15: 2.75 | B15: 25.396264 | C15: 10.9 | D15: 18.618151 | E15: 18.193684 | F15: 22.713761 | G15: 7.2640145 | H15: 23.324653 | I15: 76.759582
... A44: 10 | B44: 112.58671 | C44: 52.857671 | D44: 163.30479 | E44: 77.946392 | F44: 128.12383 | G44: 38.155039 | H44: 136.74486 | I44: 190.97436

Sheet FigS2j
A1: Spreading data of MDCK C3 samples A-G
B2: Spreading Averaged |y| displacement [μm]
A3: Time [h] | B3: Mean | C3: Sample A | D3: Sample B | E3: Sample C | F3: Sample D | G3: Sample E | H3: Sample F | I3: Sample G
A4: 0 | B4: =FigS2h!B4-FigS2i!B4 -> 0 | C4: =FigS2h!C4-FigS2i!C4 -> 0 | D4: =FigS2h!D4-FigS2i!D4 -> 0 | E4: =FigS2h!E4-FigS2i!E4 -> 0 | F4: =FigS2h!F4-FigS2i!F4 -> 0 | G4: =FigS2h!G4-FigS2i!G4 -> 0 | H4: =FigS2h!H4-FigS2i!H4 -> 0 | I4: =FigS2h!I4-FigS2i!I4 -> 0
A5: 0.25 | B5: =FigS2h!B5-FigS2i!B5 -> 1.2668058 | C5: =FigS2h!C5-FigS2i!C5 -> 0.046382189 | D5: =FigS2h!D5-FigS2i!D5 -> -3.477121 | E5: =FigS2h!E5-FigS2i!E5 -> -0.047389995 | F5: =FigS2h!F5-FigS2i!F5 -> 3.3655693 | G5: =FigS2h!G5-FigS2i!G5 -> 5.9188917 | H5: =FigS2h!H5-FigS2i!H5 -> 4.6047495 | I5: =FigS2h!I5-FigS2i!I5 -> -1.5434412
A6: 0.5 | B6: =FigS2h!B6-FigS2i!B6 -> 1.3084577 | C6: =FigS2h!C6-FigS2i!C6 -> 2.2202573 | D6: =FigS2h!D6-FigS2i!D6 -> -7.6972592 | E6: =FigS2h!E6-FigS2i!E6 -> -1.9445053 | F6: =FigS2h!F6-FigS2i!F6 -> 2.4702901 | G6: =FigS2h!G6-FigS2i!G6 -> 8.7611877 | H6: =FigS2h!H6-FigS2i!H6 -> 8.6724835 | I6: =FigS2h!I6-FigS2i!I6 -> -3.3232499
A7: 0.75 | B7: =FigS2h!B7-FigS2i!B7 -> 1.0911234 | C7: =FigS2h!C7-FigS2i!C7 -> 0.88465921 | D7: =FigS2h!D7-FigS2i!D7 -> -11.987988 | E7: =FigS2h!E7-FigS2i!E7 -> -3.9353092 | F7: =FigS2h!F7-FigS2i!F7 -> 2.1050997 | G7: =FigS2h!G7-FigS2i!G7 -> 12.810291 | H7: =FigS2h!H7-FigS2i!H7 -> 12.544601 | I7: =FigS2h!I7-FigS2i!I7 -> -4.7834903
A8: 1 | B8: =FigS2h!B8-FigS2i!B8 -> 2.6581995 | C8: =FigS2h!C8-FigS2i!C8 -> -2.0229322 | D8: =FigS2h!D8-FigS2i!D8 -> -11.306086 | E8: =FigS2h!E8-FigS2i!E8 -> -0.061188005 | F8: =FigS2h!F8-FigS2i!F8 -> 1.0150423 | G8: =FigS2h!G8-FigS2i!G8 -> 21.896948 | H8: =FigS2h!H8-FigS2i!H8 -> 16.014855 | I8: =FigS2h!I8-FigS2i!I8 -> -6.9292429
A9: 1.25 | B9: =FigS2h!B9-FigS2i!B9 -> 3.0060543 | C9: =FigS2h!C9-FigS2i!C9 -> 3.0729367 | D9: =FigS2h!D9-FigS2i!D9 -> -10.665735 | E9: =FigS2h!E9-FigS2i!E9 -> -1.9526156 | F9: =FigS2h!F9-FigS2i!F9 -> -4.3815349 | G9: =FigS2h!G9-FigS2i!G9 -> 24.465343 | H9: =FigS2h!H9-FigS2i!H9 -> 19.599936 | I9: =FigS2h!I9-FigS2i!I9 -> -9.0959509
A10: 1.5 | B10: =FigS2h!B10-FigS2i!B10 -> 2.6746176 | C10: =FigS2h!C10-FigS2i!C10 -> 0.53495361 | D10: =FigS2h!D10-FigS2i!D10 -> -9.9983456 | E10: =FigS2h!E10-FigS2i!E10 -> -1.4522299 | F10: =FigS2h!F10-FigS2i!F10 -> -4.0236098 | G10: =FigS2h!G10-FigS2i!G10 -> 22.939915 | H10: =FigS2h!H10-FigS2i!H10 -> 23.480538 | I10: =FigS2h!I10-FigS2i!I10 -> -12.758897
A11: 1.75 | B11: =FigS2h!B11-FigS2i!B11 -> 3.3447645 | C11: =FigS2h!C11-FigS2i!C11 -> 5.8627132 | D11: =FigS2h!D11-FigS2i!D11 -> -9.199804 | E11: =FigS2h!E11-FigS2i!E11 -> -6.1515264 | F11: =FigS2h!F11-FigS2i!F11 -> -2.3974487 | G11: =FigS2h!G11-FigS2i!G11 -> 23.055794 | H11: =FigS2h!H11-FigS2i!H11 -> 29.086118 | I11: =FigS2h!I11-FigS2i!I11 -> -16.842495
A12: 2 | B12: =FigS2h!B12-FigS2i!B12 -> 5.236451 | C12: =FigS2h!C12-FigS2i!C12 -> 5.0966263 | D12: =FigS2h!D12-FigS2i!D12 -> -8.3166678 | E12: =FigS2h!E12-FigS2i!E12 -> -2.3725849 | F12: =FigS2h!F12-FigS2i!F12 -> -0.89164387 | G12: =FigS2h!G12-FigS2i!G12 -> 25.997003 | H12: =FigS2h!H12-FigS2i!H12 -> 38.44585 | I12: =FigS2h!I12-FigS2i!I12 -> -21.303426
A13: 2.25 | B13: =FigS2h!B13-FigS2i!B13 -> 6.9764777 | C13: =FigS2h!C13-FigS2i!C13 -> 8.5482498 | D13: =FigS2h!D13-FigS2i!D13 -> -7.2512829 | E13: =FigS2h!E13-FigS2i!E13 -> 0.2388101 | F13: =FigS2h!F13-FigS2i!F13 -> -0.58046949 | G13: =FigS2h!G13-FigS2i!G13 -> 27.031754 | H13: =FigS2h!H13-FigS2i!H13 -> 46.953688 | I13: =FigS2h!I13-FigS2i!I13 -> -26.105405
A14: 2.5 | B14: =FigS2h!B14-FigS2i!B14 -> 7.6015046 | C14: =FigS2h!C14-FigS2i!C14 -> 8.2644724 | D14: =FigS2h!D14-FigS2i!D14 -> -6.1000947 | E14: =FigS2h!E14-FigS2i!E14 -> -5.6598533 | F14: =FigS2h!F14-FigS2i!F14 -> 2.6861445 | G14: =FigS2h!G14-FigS2i!G14 -> 29.0496 | H14: =FigS2h!H14-FigS2i!H14 -> 46.600865 | I14: =FigS2h!I14-FigS2i!I14 -> -21.630602
A15: 2.75 | B15: =FigS2h!B15-FigS2i!B15 -> 9.234679 | C15: =FigS2h!C15-FigS2i!C15 -> 8.9211538 | D15: =FigS2h!D15-FigS2i!D15 -> -5.1665378 | E15: =FigS2h!E15-FigS2i!E15 -> -4.4075679 | F15: =FigS2h!F15-FigS2i!F15 -> 1.2691607 | G15: =FigS2h!G15-FigS2i!G15 -> 34.203673 | H15: =FigS2h!H15-FigS2i!H15 -> 48.247982 | I15: =FigS2h!I15-FigS2i!I15 -> -18.425111
... A44: 10 | B44: =FigS2h!B44-FigS2i!B44 -> 29.751623 | C44: =FigS2h!C44-FigS2i!C44 -> 47.421959 | D44: =FigS2h!D44-FigS2i!D44 -> -79.355815 | E44: =FigS2h!E44-FigS2i!E44 -> 12.97655 | F44: =FigS2h!F44-FigS2i!F44 -> 8.351083 | G44: =FigS2h!G44-FigS2i!G44 -> 181.5016 | H44: =FigS2h!H44-FigS2i!H44 -> 15.887963 | I44: =FigS2h!I44-FigS2i!I44 -> 21.478022

Sheet FigS3b
A1: Data of All MCF10a samples (N=40)
B2: Averaged |y| displacement [μm]
A3: Time [h] | B3: Front | C3: Rear | D3: Spreading
A4: 0 | B4: 0 | C4: 0 | D4: 0
A5: 0.25 | B5: 5.5831411 | C5: 4.8588948 | D5: 0.72424627
A6: 0.5 | B6: 10.808698 | C6: 9.0359716 | D6: 1.7727261
A7: 0.75 | B7: 15.138658 | C7: 13.965575 | D7: 1.1730828
A8: 1 | B8: 20.200664 | C8: 17.460797 | D8: 2.7398677
A9: 1.25 | B9: 25.023695 | C9: 21.958171 | D9: 3.0655243
A10: 1.5 | B10: 30.553053 | C10: 27.209528 | D10: 3.3435245
A11: 1.75 | B11: 36.006478 | C11: 31.901968 | D11: 4.1045099
A12: 2 | B12: 41.013418 | C12: 36.582842 | D12: 4.4305759
A13: 2.25 | B13: 46.433803 | C13: 41.906229 | D13: 4.5275745
A14: 2.5 | B14: 52.64151 | C14: 47.668909 | D14: 4.9726003
A15: 2.75 | B15: 57.854418 | C15: 52.743415 | D15: 5.1110036
... A44: 10 | B44: 233.42617 | C44: 238.52317 | D44: -5.0970079

Sheet FigS3a
A1: Data of All MDCK samples (N=57)
B2: Averaged |y| displacement [μm]
A3: Time [h] | B3: Front | C3: Rear | D3: Spreading
A4: 0 | B4: 0 | C4: 0 | D4: 0
A5: 0.25 | B5: 4.2257377 | C5: 3.6764572 | D5: 0.54928043
A6: 0.5 | B6: 7.6589961 | C6: 6.6312136 | D6: 1.0277825
A7: 0.75 | B7: 11.287499 | C7: 10.191371 | D7: 1.0961282
A8: 1 | B8: 15.034937 | C8: 13.260524 | D8: 1.7744136
A9: 1.25 | B9: 18.84876 | C9: 16.707367 | D9: 2.1413929
A10: 1.5 | B10: 22.732909 | C10: 20.215957 | D10: 2.5169522
A11: 1.75 | B11: 27.157754 | C11: 24.222359 | D11: 2.9353948
A12: 2 | B12: 31.839849 | C12: 28.670389 | D12: 3.1694596
A13: 2.25 | B13: 37.215402 | C13: 33.312744 | D13: 3.9026578
A14: 2.5 | B14: 42.699226 | C14: 38.255264 | D14: 4.4439612
A15: 2.75 | B15: 47.412254 | C15: 42.604574 | D15: 4.8076801
... A44: 10 | B44: 181.25181 | C44: 170.514 | D44: 10.737808

Sheet MDCK-front
A1: Front data of All MDCK samples (N=57) | E1: Averaged |y| displacement [μm]
B2: A3 | E2: B1 | H2: B2 | P2: B3 | AC2: C1 | AF2: C2 | AK2: C3 | AR2: D1 | AT2: D2 | BA2: D3
A3: Time [h] | B3: Sample A | C3: Sample B | D3: Sample C | E3: Sample A | F3: Sample B | G3: Sample C | H3: Sample A | I3: Sample B | J3: Sample C | K3: Sample D | L3: Sample E | M3: Sample F | N3: Sample G | O3: Sample H | P3: Sample A | Q3: Sample B | R3: Sample C | S3: Sample D | T3: Sample E | U3: Sample F | V3: Sample G | W3: Sample H | X3: Sample I | Y3: Sample J | Z3: Sample K | AA3: Sample L | AB3: Sample M | AC3: Sample A | AD3: Sample B | AE3: Sample C | AF3: Sample A | AG3: Sample B | AH3: Sample C | AI3: Sample D | AJ3: Sample E | AK3: Sample A | AL3: Sample B | AM3: Sample C | AN3: Sample D | AO3: Sample E | AP3: Sample F | AQ3: Sample G | AR3: Sample A | AS3: Sample B | AT3: Sample A | AU3: Sample B | AV3: Sample C | AW3: Sample D | AX3: Sample E | AY3: Sample F | AZ3: Sample G | BA3: Sample A | BB3: Sample B | BC3: Sample C | BD3: Sample D | BE3: Sample E | BF3: Sample F
A4: 0 | B4: 0 | C4: 0 | D4: 0 | E4: 0 | F4: 0 | G4: 0 | H4: 0 | I4: 0 | J4: 0 | K4: 0 | L4: 0 | M4: 0 | N4: 0 | O4: 0 | P4: 0 | Q4: 0 | R4: 0 | S4: 0 | T4: 0 | U4: 0 | V4: 0 | W4: 0 | X4: 0 | Y4: 0 | Z4: 0 | AA4: 0 | AB4: 0 | AC4: 0 | AD4: 0 | AE4: 0 | AF4: 0 | AG4: 0 | AH4: 0 | AI4: 0 | AJ4: 0 | AK4: 0 | AL4: 0 | AM4: 0 | AN4: 0 | AO4: 0 | AP4: 0 | AQ4: 0 | AR4: 0 | AS4: 0 | AT4: 0 | AU4: 0 | AV4: 0 | AW4: 0 | AX4: 0 | AY4: 0 | AZ4: 0 | BA4: 0 | BB4: 0 | BC4: 0 | BD4: 0 | BE4: 0 | BF4: 0
A5: 0.25 | B5: 5.4141593 | C5: 4.4158249 | D5: 0.65816327 | E5: 0.04787234 | F5: 0.68817204 | G5: 0.89617486 | H5: 0.27203065 | I5: 1.2482877 | J5: 3.7271186 | K5: 2.4657534 | L5: 3.976234 | M5: 11.15 | N5: 7.7135678 | O5: 3.6306914 | P5: 0.44162437 | Q5: 2.8358714 | R5: 2.8023064 | S5: 2.2222222 | T5: 7.8795987 | U5: 5.5431472 | V5: 0.43097643 | W5: 11.462838 | X5: 6.8573854 | Y5: 5.1764706 | Z5: 5.7173913 | AA5: 7.6613475 | AB5: 3.7647059 | AC5: 4.5351351 | AD5: 3.2041885 | AE5: 0.19354839 | AF5: 4.5525362 | AG5: 1.1634446 | AH5: 3.0119863 | AI5: 4.687813 | AJ5: 6.6521739 | AK5: 1.0463822 | AL5: 1.0051724 | AM5: 0.58633094 | AN5: 5.5064695 | AO5: 7.5807623 | AP5: 6.6064736 | AQ5: 3.7717206 | AR5: 0.54794521 | AS5: 4.5915254 | AT5: 1.6954225 | AU5: 5.7645951 | AV5: 6.5025042 | AW5: 4.9508197 | AX5: 14.403419 | AY5: 6.1663837 | AZ5: 7.2281879 | BA5: 3.0204778 | BB5: 1.4991653 | BC5: 4.3321617 | BD5: 6.4220339 | BE5: 6.4433333 | BF5: 4.095
A6: 0.5 | B6: 6.3059829 | C6: 7.3525424 | D6: 2.4400685 | E6: 0.27956989 | F6: 1.4255319 | G6: 0.89617486 | H6: 2.6578947 | I6: 2.1101549 | J6: 7.0994941 | K6: 4.5986278 | L6: 10.3125 | M6: 18.806452 | N6: 15.304493 | O6: 6.5566836 | P6: 0.35204082 | Q6: 5.9765886 | R6: 2.0776014 | S6: 3.9795918 | T6: 15.664992 | U6: 11.048904 | V6: 1.1402027 | W6: 22.134003 | X6: 16.457831 | Y6: 13.408088 | Z6: 9.6905594 | AA6: 11.849442 | AB6: 7.170068 | AC6: 8.826087 | AD6: 6.0662983 | AE6: 0.010526316 | AF6: 9.6101399 | AG6: 2.3835616 | AH6: 2.345614 | AI6: 8.7325581 | AJ6: 5.3292683 | AK6: 2.2556391 | AL6: 1.9187817 | AM6: 0.99299475 | AN6: 6.6927273 | AO6: 13.448454 | AP6: 12.282828 | AQ6: 7.2272727 | AR6: 0.40131579 | AS6: 8.7925801 | AT6: 0.72089041 | AU6: 7.0116505 | AV6: 12.643216 | AW6: 6.626151 | AX6: 28.265411 | AY6: 12.261905 | AZ6: 14.059603 | BA6: 5.4253859 | BB6: 6.6122449 | BC6: 5.3118467 | BD6: 12.751678 | BE6: 12.44 | BF6: 8.0200669
A7: 0.75 | B7: 10.510417 | C7: 11.933333 | D7: 0.7008547 | E7: 0.69230769 | F7: 1.9489796 | G7: 0.9076087 | H7: 4.1779359 | I7: 2.2318584 | J7: 10.334459 | K7: 6.9622642 | L7: 17.623188 | M7: 27.182444 | N7: 23.466003 | O7: 9.903172 | P7: 0.077571669 | Q7: 8.9865772 | R7: 7.0282392 | S7: 5.851602 | T7: 24.627946 | U7: 16.741935 | V7: 1.7231834 | W7: 33.132773 | X7: 20.544815 | Y7: 18.81338 | Z7: 12.753719 | AA7: 16.774492 | AB7: 10.569728 | AC7: 13.294737 | AD7: 8.6157895 | AE7: 0.10326087 | AF7: 14.603093 | AG7: 4.5603448 | AH7: 2.9326599 | AI7: 13.489933 | AJ7: 6.0757042 | AK7: 1.7573529 | AL7: 3.9608177 | AM7: 0.23302752 | AN7: 8.2640145 | AO7: 17.920071 | AP7: 18.018739 | AQ7: 11.113946 | AR7: 1.6789474 | AS7: 13.301695 | AT7: 0.53141831 | AU7: 9.3852295 | AV7: 19.262267 | AW7: 12.629693 | AX7: 42.084602 | AY7: 18.632997 | AZ7: 21.41806 | BA7: 7.9776248 | BB7: 6.3484321 | BC7: 9.0368509 | BD7: 19.372014 | BE7: 18.627119 | BF7: 11.956229
A8: 1 | B8: 10.97373 | C8: 16.228769 | D8: 6.3596639 | E8: 0.83157895 | F8: 2.4064171 | G8: 0.93513514 | H8: 5.454902 | I8: 3.0936455 | J8: 13.616695 | K8: 8.9982993 | L8: 25.49522 | M8: 37.038596 | N8: 31.896494 | O8: 13.060201 | P8: 0.24958124 | Q8: 12.773109 | R8: 7.4755481 | S8: 7.5548061 | T8: 35.545608 | U8: 22.709898 | V8: 2.3310924 | W8: 44.320405 | X8: 26.494863 | Y8: 23.142336 | Z8: 13.537543 | AA8: 24.622263 | AB8: 13.959253 | AC8: 17.646409 | AD8: 11.530726 | AE8: 0.066666667 | AF8: 20.021164 | AG8: 5.1008547 | AH8: 2.9621928 | AI8: 17.936982 | AJ8: 9.9365352 | AK8: 0.21543986 | AL8: 4.8771331 | AM8: 4.336163 | AN8: 8.4343972 | AO8: 22.613139 | AP8: 23.313131 | AQ8: 15.075885 | AR8: 0.18823529 | AS8: 18.015228 | AT8: 0.2305026 | AU8: 12.009823 | AV8: 26.164686 | AW8: 13.596581 | AX8: 56.298305 | AY8: 27.597293 | AZ8: 29.164154 | BA8: 10.631399 | BB8: 8.7303571 | BC8: 11.575862 | BD8: 26.380546 | BE8: 24.928814 | BF8: 16.307179
A9: 1.25 | B9: 16.017452 | C9: 22.468421 | D9: 7.9878472 | E9: 1.0322581 | F9: 2.8181818 | G9: 0.76344086 | H9: 5.7179963 | I9: 5.3512111 | J9: 17.290816 | K9: 11.08769 | L9: 31.44964 | M9: 37.929293 | N9: 40.897181 | O9: 16.246622 | P9: 0.1769616 | Q9: 15.679595 | R9: 5.6748252 | S9: 9.3378608 | T9: 39.724832 | U9: 28.981324 | V9: 2.9536878 | W9: 56.0625 | X9: 34.041739 | Y9: 28.4 | Z9: 18.24744 | AA9: 30.607266 | AB9: 17.171186 | AC9: 22.010753 | AD9: 14.263736 | AE9: 0.25789474 | AF9: 23.101266 | AG9: 7.3499142 | AH9: 3.4932432 | AI9: 22.875839 | AJ9: 13.193548 | AK9: 6.0729367 | AL9: 5.7231544 | AM9: 3.5976027 | AN9: 8.6316726 | AO9: 26.585911 | AP9: 28.574074 | AQ9: 19.830795 | AR9: 0.55345912 | AS9: 23.523569 | AT9: 0.10606061 | AU9: 15.796992 | AV9: 33.341216 | AW9: 21.803191 | AX9: 66.496599 | AY9: 39.050167 | AZ9: 37.456229 | BA9: 13.274276 | BB9: 12.21 | BC9: 14.847751 | BD9: 34.057725 | BE9: 31.670628 | BF9: 20.511824
A10: 1.5 | B10: 15.397959 | C10: 27.241796 | D10: 8.9097345 | E10: 1.2432432 | F10: 3.8241206 | G10: 0.54639175 | H10: 9.0946429 | I10: 5.937833 | J10: 20.661074 | K10: 13.234401 | L10: 38.486583 | M10: 47.772881 | N10: 50.234114 | O10: 19.523891 | P10: 0.12351946 | Q10: 18.696309 | R10: 4.1033868 | S10: 11.236797 | T10: 43.696309 | U10: 35.417508 | V10: 3.6444444 | W10: 69.170358 | X10: 46.240484 | Y10: 31.75365 | Z10: 22.42446 | AA10: 42.731397 | AB10: 20.645973 | AC10: 26.633333 | AD10: 16.956757 | AE10: 0.18041237 | AF10: 26.597015 | AG10: 8.0588235 | AH10: 3.7208481 | AI10: 28.005051 | AJ10: 13.405546 | AK10: 4.9980916 | AL10: 6.7576271 | AM10: 5.6805324 | AN10: 9.5376147 | AO10: 27.825312 | AP10: 34.428814 | AQ10: 24.305228 | AR10: 1.9897436 | AS10: 30.576271 | AT10: 0.46750903 | AU10: 18.125704 | AV10: 41.47449 | AW10: 23.782765 | AX10: 76.764407 | AY10: 50.792988 | AZ10: 46.162521 | BA10: 15.587838 | BB10: 12.33391 | BC10: 22.573192 | BD10: 42.203046 | BE10: 38.889447 | BF10: 24.967742
A11: 1.75 | B11: 20.219684 | C11: 32.497409 | D11: 12.006838 | E11: 1.4603175 | F11: 3.7842105 | G11: 0.56185567 | H11: 10.08489 | I11: 8.7259786 | J11: 24.514382 | K11: 15.712095 | L11: 48.283054 | M11: 54.278547 | N11: 60.376667 | O11: 23.284512 | P11: 0.35510888 | Q11: 21.353821 | R11: 7.0536585 | S11: 12.914384 | T11: 48.38255 | U11: 42.626486 | V11: 4.3056027 | W11: 84.189597 | X11: 55.188612 | Y11: 39.985047 | Z11: 25.711893 | AA11: 52.511029 | AB11: 24.036975 | AC11: 30.908108 | AD11: 19.983871 | AE11: 0.020618557 | AF11: 27.564544 | AG11: 10.517241 | AH11: 4.4803419 | AI11: 33.396667 | AJ11: 16.07069 | AK11: 7.5687023 | AL11: 7.8260135 | AM11: 7.8020134 | AN11: 12.633028 | AO11: 27.55036 | AP11: 41.810256 | AQ11: 28.939292 | AR11: 0.47340426 | AS11: 39.045997 | AT11: 1.6917688 | AU11: 23.497076 | AV11: 50.034072 | AW11: 28.10219 | AX11: 87.292808 | AY11: 63.440735 | AZ11: 57.888325 | BA11: 18.567063 | BB11: 13.708126 | BC11: 25.844221 | BD11: 50.018836 | BE11: 47.010067 | BF11: 29.900338
A12: 2 | B12: 24.268041 | C12: 36.959292 | D12: 14.235395 | E12: 1.9677419 | F12: 4.65625 | G12: 0.96276596 | H12: 10.127042 | I12: 7.9965928 | J12: 28.208829 | K12: 17.719864 | L12: 59.02993 | M12: 64.013817 | N12: 70.101836 | O12: 26.796265 | P12: 0.43529412 | Q12: 24.223333 | R12: 6.3691508 | S12: 14.757576 | T12: 54.737733 | U12: 49.447811 | V12: 4.897084 | W12: 102.022 | X12: 60.035088 | Y12: 46.495512 | Z12: 33.60469 | AA12: 61.614232 | AB12: 27.631134 | AC12: 35.327869 | AD12: 23.010638 | AE12: 0.25773196 | AF12: 28.934932 | AG12: 11.159475 | AH12: 4.8174061 | AI12: 39.257576 | AJ12: 16.201709 | AK12: 9.8394834 | AL12: 9.0503356 | AM12: 10.553415 | AN12: 14.360294 | AO12: 30.913824 | AP12: 53.027165 | AQ12: 34.287879 | AR12: 3.127907 | AS12: 48.646758 | AT12: 3.4389381 | AU12: 27.90411 | AV12: 60.032258 | AW12: 32.59507 | AX12: 98.658076 | AY12: 76.087102 | AZ12: 70.85906 | BA12: 21.044068 | BB12: 18.076512 | BC12: 30.778333 | BD12: 58.503378 | BE12: 55.50678 | BF12: 35.299003
A13: 2.25 | B13: 24.843434 | C13: 43.030928 | D13: 21.998252 | E13: 2.8913043 | F13: 5.7393617 | G13: 0.92146597 | H13: 14.220183 | I13: 8.3745645 | J13: 33.062818 | K13: 20.629693 | L13: 66.634752 | M13: 67.126316 | N13: 81.057239 | O13: 32.194631 | P13: 0.042016807 | Q13: 28.199324 | R13: 6.8857616 | S13: 17.313356 | T13: 64.723906 | U13: 58.433447 | V13: 6.0508475 | W13: 120.44054 | X13: 65.908475 | Y13: 52.729008 | Z13: 36.923841 | AA13: 70.643225 | AB13: 31.940577 | AC13: 40.690608 | AD13: 26.806452 | AE13: 0.39896373 | AF13: 30.945205 | AG13: 13.279646 | AH13: 4.2945591 | AI13: 46.388333 | AJ13: 25.222798 | AK13: 12.925859 | AL13: 10.624138 | AM13: 14.84456 | AN13: 17.89414 | AO13: 32.478114 | AP13: 64.136594 | AQ13: 40.89983 | AR13: 4.4072165 | AS13: 60.989813 | AT13: 4.8537037 | AU13: 30.93271 | AV13: 73.006768 | AW13: 39.952297 | AX13: 112.19355 | AY13: 90.766892 | AZ13: 87.437396 | BA13: 24.711604 | BB13: 20.521739 | BC13: 31.023891 | BD13: 68.217905 | BE13: 66.065217 | BF13: 41.408163
A14: 2.5 | B14: 29.379725 | C14: 49.573427 | D14: 27.575085 | E14: 2.5189189 | F14: 7.0478723 | G14: 0.54098361 | H14: 12.979167 | I14: 8.2716667 | J14: 37.253807 | K14: 28.938776 | L14: 80.007117 | M14: 69.591973 | N14: 90.705882 | O14: 33.461929 | P14: 0.67802385 | Q14: 33.262626 | R14: 9.8576214 | S14: 23.340067 | T14: 79.173109 | U14: 65.402357 | V14: 8.3512111 | W14: 131.21536 | X14: 93.169091 | Y14: 68.618868 | Z14: 42.886986 | AA14: 76.296846 | AB14: 36.863176 | AC14: 43.833333 | AD14: 30.645833 | AE14: 2.1666667 | AF14: 30.06367 | AG14: 12.737705 | AH14: 3.533107 | AI14: 53.127483 | AJ14: 32.693241 | AK14: 14.694683 | AL14: 11.87585 | AM14: 11.380454 | AN14: 22.364991 | AO14: 36.506849 | AP14: 67.037607 | AQ14: 49.904682 | AR14: 3.265625 | AS14: 72.037225 | AT14: 4.8246528 | AU14: 33.81382 | AV14: 86.119658 | AW14: 43.058407 | AX14: 126.27835 | AY14: 96.436027 | AZ14: 100.28691 | BA14: 28.574871 | BB14: 23.010204 | BC14: 39.267504 | BD14: 80.087542 | BE14: 79.8 | BF14: 47.467227
A15: 2.75 | B15: 33.64094 | C15: 55.626761 | D15: 30.712585 | E15: 4.2989691 | F15: 8.0412371 | G15: 1.4 | H15: 14.981917 | I15: 8.4855688 | J15: 41.128596 | K15: 37.405822 | L15: 99.577391 | M15: 76.615652 | N15: 99.63228 | O15: 34.79357 | P15: 1.0698467 | Q15: 37.01 | R15: 6.1301989 | S15: 29.370805 | T15: 92.36163 | U15: 73.646259 | V15: 10.018868 | W15: 139.62729 | X15: 96.812825 | Y15: 66.461538 | Z15: 48.721843 | AA15: 90.30853 | AB15: 41.275804 | AC15: 46.445652 | AD15: 33.320856 | AE15: 4.5706806 | AF15: 30.881481 | AG15: 13.031773 | AH15: 3.6291161 | AI15: 58.72621 | AJ15: 38.956747 | AK15: 19.821154 | AL15: 13.451613 | AM15: 13.786116 | AN15: 23.982922 | AO15: 41.467687 | AP15: 71.572635 | AQ15: 58.334471 | AR15: 5.962963 | AS15: 81.728499 | AT15: 2.7368421 | AU15: 38.515596 | AV15: 97.539898 | AW15: 44.297872 | AX15: 136.23932 | AY15: 101.04319 | AZ15: 113.3194 | BA15: 32.127586 | BB15: 23.853952 | BC15: 41.936057 | BD15: 89.046075 | BE15: 90.989933 | BF15: 52.025467
... A44: 10 | B44: 134.35612 | C44: 201.7027 | D44: 128.71786 | E44: 51.780105 | F44: 45.858639 | G44: 19.692708 | H44: 71.685714 | I44: 48.814503 | J44: 137.2027 | K44: 285.55782 | L44: 347.70232 | M44: 168.60708 | N44: 299.45777 | O44: 69.538851 | P44: 54.011844 | Q44: 129.91304 | R44: 30.863787 | S44: 222.42105 | T44: 374.87879 | U44: 288.52872 | V44: 64.050505 | W44: 312.01178 | X44: 253.68591 | Y44: 313.93659 | Z44: 196.15763 | AA44: 419.16928 | AB44: 174.37669 | AC44: 205.55435 | AD44: 98.225806 | AE44: 1.3402062 | AF44: 55.623264 | AG44: 58.507745 | AH44: 16.195691 | AI44: 269.96447 | AJ44: 184.80617 | AK44: 100.27963 | AL44: 83.94898 | AM44: 90.922942 | AN44: 136.47491 | AO44: 219.65664 | AP44: 152.63283 | AQ44: 212.45238 | AR44: 29.987179 | AS44: 357.05932 | AT44: 16.69964 | AU44: 110.24259 | AV44: 396.5906 | AW44: 213.36042 | AX44: 393.82572 | AY44: 379.23181 | AZ44: 322.57046 | BA44: 115.85274 | BB44: 104.54246 | BC44: 207.10085 | BD44: 404.22109 | BE44: 381.91582 | BF44: 166.8861

Sheet MDCK-rear
A1: Rear data of All MDCK samples (N=57)
B2: A3 | E2: B1 | H2: B2 | P2: B3 | AC2: C1 | AF2: C2 | AK2: C3 | AR2: D1 | AT2: D2 | BA2: D3
A3: Time [h] | B3: Sample A | C3: Sample B | D3: Sample C | E3: Sample A | F3: Sample B | G3: Sample C | H3: Sample A | I3: Sample B | J3: Sample C | K3: Sample D | L3: Sample E | M3: Sample F | N3: Sample G | O3: Sample H | P3: Sample A | Q3: Sample B | R3: Sample C | S3: Sample D | T3: Sample E | U3: Sample F | V3: Sample G | W3: Sample H | X3: Sample I | Y3: Sample J | Z3: Sample K | AA3: Sample L | AB3: Sample M | AC3: Sample A | AD3: Sample B | AE3: Sample C | AF3: Sample A | AG3: Sample B | AH3: Sample C | AI3: Sample D | AJ3: Sample E | AK3: Sample A | AL3: Sample B | AM3: Sample C | AN3: Sample D | AO3: Sample E | AP3: Sample F | AQ3: Sample G | AR3: Sample A | AS3: Sample B | AT3: Sample A | AU3: Sample B | AV3: Sample C | AW3: Sample D | AX3: Sample E | AY3: Sample F | AZ3: Sample G | BA3: Sample A | BB3: Sample B | BC3: Sample C | BD3: Sample D | BE3: Sample E | BF3: Sample F
A4: 0 | B4: 0 | C4: 0 | D4: 0 | E4: 0 | F4: 0 | G4: 0 | H4: 0 | I4: 0 | J4: 0 | K4: 0 | L4: 0 | M4: 0 | N4: 0 | O4: 0 | P4: 0 | Q4: 0 | R4: 0 | S4: 0 | T4: 0 | U4: 0 | V4: 0 | W4: 0 | X4: 0 | Y4: 0 | Z4: 0 | AA4: 0 | AB4: 0 | AC4: 0 | AD4: 0 | AE4: 0 | AF4: 0 | AG4: 0 | AH4: 0 | AI4: 0 | AJ4: 0 | AK4: 0 | AL4: 0 | AM4: 0 | AN4: 0 | AO4: 0 | AP4: 0 | AQ4: 0 | AR4: 0 | AS4: 0 | AT4: 0 | AU4: 0 | AV4: 0 | AW4: 0 | AX4: 0 | AY4: 0 | AZ4: 0 | BA4: 0 | BB4: 0 | BC4: 0 | BD4: 0 | BE4: 0 | BF4: 0
A5: 0.25 | B5: 3.9928315 | C5: 4.9144385 | D5: 2.7216117 | E5: 0.83333333 | F5: 2.4777778 | G5: 0.9 | H5: 11.635438 | I5: 1.6113445 | J5: 3.7586207 | K5: 7.862069 | L5: 2.8542805 | M5: 2.7134503 | N5: 1.8206897 | O5: 4.9947735 | P5: 1.8551724 | Q5: 2.6551724 | R5: 1.124 | S5: 4.4482759 | T5: 9.467128 | U5: 4.0327586 | V5: 1.492228 | W5: 7.9 | X5: 6.4713494 | Y5: 1.6883803 | Z5: 7.5140713 | AA5: 2.1942446 | AB5: 12.632404 | AC5: 0.86666667 | AD5: 1.0555556 | AE5: 1.8888889 | AF5: 2.1135903 | AG5: 1.0588235 | AH5: 1.214425 | AI5: 4.2965517 | AJ5: 4.3021583 | AK5: 1 | AL5: 4.4822934 | AM5: 0.63372093 | AN5: 2.1409002 | AO5: 1.6618705 | AP5: 2.0017241 | AQ5: 5.3151618 | AR5: 1.35 | AS5: 3.9134126 | AT5: 1.1468813 | AU5: 0.59328358 | AV5: 7.9727891 | AW5: 0.021696252 | AX5: 5.5172414 | AY5: 12.124138 | AZ5: 4.5758621 | BA5: 0.64827586 | BB5: 1.252809 | BC5: 3.0444874 | BD5: 5.3603448 | BE5: 6.8655172 | BF5: 4.5731497
A6: 0.5 | B6: 8.4538879 | C6: 7.1934901 | D6: 2.9408503 | E6: 1.5555556 | F6: 4.2611111 | G6: 1.4666667 | H6: 8.3608445 | I6: 1.8390152 | J6: 7.2241379 | K6: 15.462069 | L6: 7.9825581 | M6: 2.7741935 | N6: 3.2241379 | O6: 9.3245614 | P6: 3.1793103 | Q6: 4.7586207 | R6: 0.34008097 | S6: 8.2137931 | T6: 19.121107 | U6: 7.812069 | V6: 2.299308 | W6: 15.743103 | X6: 9.6726619 | Y6: 6.8850365 | Z6: 4.8939394 | AA6: 3.0283688 | AB6: 24.677138 | AC6: 0.72222222 | AD6: 1.8944444 | AE6: 3.5222222 | AF6: 5.7759674 | AG6: 0.9148073 | AH6: 1.5920792 | AI6: 8.0068966 | AJ6: 2.1798165 | AK6: 0.03538175 | AL6: 9.616041 | AM6: 2.9375 | AN6: 4.2224371 | AO6: 4.6872659 | AP6: 3.6103448 | AQ6: 10.550523 | AR6: 0.01010101 | AS6: 7.2517123 | AT6: 0.57459677 | AU6: 8.2042254 | AV6: 15.242735 | AW6: 6.3527132 | AX6: 10.703448 | AY6: 24.206897 | AZ6: 8.5034483 | BA6: 1.1758621 | BB6: 4.0877514 | BC6: 6.7155797 | BD6: 10.210345 | BE6: 13.062069 | BF6: 8.7221269
A7: 0.75 | B7: 14.356522 | C7: 11.10991 | D7: 7.6119403 | E7: 2.1388889 | F7: 6.5222222 | G7: 2.1333333 | H7: 9.7912713 | I7: 1.5291667 | J7: 11.089655 | K7: 23.531034 | L7: 10.551136 | M7: 2.8505535 | N7: 4.7913793 | O7: 14.076923 | P7: 4.887931 | Q7: 7.2965517 | R7: 2.8778004 | S7: 12.136207 | T7: 29.221254 | U7: 11.77931 | V7: 3.467128 | W7: 23.758621 | X7: 9.5194085 | Y7: 12.468124 | Z7: 14.141454 | AA7: 10.370166 | AB7: 36.722222 | AC7: 0.62222222 | AD7: 2.8555556 | AE7: 5.5222222 | AF7: 7.0383747 | AG7: 1.8672032 | AH7: 3.718107 | AI7: 12.015517 | AJ7: 2.6949458 | AK7: 0.87269373 | AL7: 15.948805 | AM7: 4.1683367 | AN7: 6.1589147 | AO7: 5.1097804 | AP7: 5.4741379 | AQ7: 15.897436 | AR7: 2.4387755 | AS7: 11.106419 | AT7: 1.3649194 | AU7: 11.035026 | AV7: 23.085069 | AW7: 12.567194 | AX7: 15.587931 | AY7: 37.27069 | AZ7: 12.653448 | BA7: 1.9034483 | BB7: 6.904936 | BC7: 6.6856061 | BD7: 15.155172 | BE7: 19.462069 | BF7: 12.99308
A8: 1 | B8: 19.033333 | C8: 15.14795 | D8: 8.1960432 | E8: 2.7166667 | F8: 8.7277778 | G8: 2.7888889 | H8: 9.4164948 | I8: 2.0708333 | J8: 14.917241 | K8: 31.351724 | L8: 16.486538 | M8: 7.9126394 | N8: 6.2586207 | O8: 19.194444 | P8: 6.2137931 | Q8: 10.187931 | R8: 3.8757895 | S8: 16.060345 | T8: 40.187391 | U8: 15.741379 | V8: 4.2318339 | W8: 32 | X8: 14.797891 | Y8: 15.786738 | Z8: 22.123188 | AA8: 14.440154 | AB8: 48.44714 | AC8: 0.77777778 | AD8: 3.5555556 | AE8: 7.1777778 | AF8: 7.8333333 | AG8: 3.9797571 | AH8: 2.1775148 | AI8: 16.018966 | AJ8: 2.1366782 | AK8: 2.2383721 | AL8: 16.183219 | AM8: 4.397351 | AN8: 7.4193548 | AO8: 0.71619048 | AP8: 7.2982759 | AQ8: 22.005128 | AR8: 0.95 | AS8: 13.789384 | AT8: 2.32282 | AU8: 9.7381818 | AV8: 30.974271 | AW8: 13.747082 | AX8: 21.324138 | AY8: 52.338435 | AZ8: 16.731749 | BA8: 2.3482759 | BB8: 9.4428822 | BC8: 6.0630798 | BD8: 19.913793 | BE8: 25.810345 | BF8: 18.1274
A9: 1.25 | B9: 22.425225 | C9: 18.010772 | D9: 9.830292 | E9: 3.4 | F9: 10.916667 | G9: 3.2333333 | H9: 13.905138 | I9: 1.7219917 | J9: 19.344887 | K9: 39.765112 | L9: 21.195402 | M9: 11.382066 | N9: 7.8344828 | O9: 25.202443 | P9: 7.6137931 | Q9: 18.372414 | R9: 4.9489362 | S9: 19.974138 | T9: 48.338515 | U9: 19.496552 | V9: 5.3246978 | W9: 41.355401 | X9: 17.150659 | Y9: 20.083488 | Z9: 23.076208 | AA9: 18.097297 | AB9: 60.521664 | AC9: 0.72222222 | AD9: 5 | AE9: 8.9611111 | AF9: 7.117284 | AG9: 3.932377 | AH9: 3.8794926 | AI9: 19.972414 | AJ9: 5.4622144 | AK9: 3 | AL9: 16.388889 | AM9: 5.5502183 | AN9: 13.013208 | AO9: 2.1205674 | AP9: 8.9741379 | AQ9: 28.926746 | AR9: 0.35 | AS9: 17.092308 | AT9: 3.4262626 | AU9: 15.657293 | AV9: 39.901893 | AW9: 17.440154 | AX9: 27.913793 | AY9: 63.001724 | AZ9: 20.875433 | BA9: 2.9034483 | BB9: 10.107774 | BC9: 6.6604128 | BD9: 24.768966 | BE9: 32.448276 | BF9: 24.229706
A10: 1.5 | B10: 26.501832 | C10: 23.326889 | D10: 11.558394 | E10: 3.8333333 | F10: 12.627778 | G10: 4.0444444 | H10: 10.199609 | I10: 1.4924528 | J10: 24.62543 | K10: 49.37931 | L10: 24.445087 | M10: 14.187377 | N10: 9.1448276 | O10: 32.006908 | P10: 9.1448276 | Q10: 26.455172 | R10: 4.7946612 | S10: 23.87931 | T10: 55.655348 | U10: 23.565517 | V10: 6.3959044 | W10: 53.027634 | X10: 18.922642 | Y10: 31.427046 | Z10: 25.303774 | AA10: 19.746903 | AB10: 73.005226 | AC10: 0.71111111 | AD10: 5.6666667 | AE10: 10.670391 | AF10: 9.3237113 | AG10: 4.3555556 | AH10: 3.8495763 | AI10: 24.068966 | AJ10: 9.2255245 | AK10: 4.463138 | AL10: 16.755973 | AM10: 7.1327623 | AN10: 13.561224 | AO10: 4.8853974 | AP10: 10.948276 | AQ10: 37.064125 | AR10: 0.45 | AS10: 20.389744 | AT10: 2.8606061 | AU10: 18.642606 | AV10: 49.366438 | AW10: 22.05501 | AX10: 33.931034 | AY10: 72.394783 | AZ10: 25.339623 | BA10: 3.3862069 | BB10: 15.707965 | BC10: 6.850365 | BD10: 29.884483 | BE10: 39.019097 | BF10: 30.651568
A11: 1.75 | B11: 31.163043 | C11: 29.619718 | D11: 11.947955 | E11: 4.5722222 | F11: 15.222222 | G11: 4.7833333 | H11: 12.923541 | I11: 4.6464435 | J11: 30.483705 | K11: 62.546248 | L11: 25.529412 | M11: 20.236893 | N11: 10.77931 | O11: 39.872154 | P11: 10.663793 | Q11: 34.351724 | R11: 5.0442656 | S11: 27.903448 | T11: 62.348958 | U11: 27.462069 | V11: 7.5017123 | W11: 66.182444 | X11: 24.118959 | Y11: 38.54159 | Z11: 36.084906 | AA11: 24.928819 | AB11: 85.993007 | AC11: 0.88888889 | AD11: 6.05 | AE11: 12.622222 | AF11: 10.247216 | AG11: 6.3501006 | AH11: 5.0313152 | AI11: 27.925862 | AJ11: 6.868231 | AK11: 1.7059891 | AL11: 17.025818 | AM11: 13.95354 | AN11: 15.030476 | AO11: 4.4945652 | AP11: 12.724138 | AQ11: 45.781787 | AR11: 3.68 | AS11: 23.864957 | AT11: 2.4878543 | AU11: 18.956522 | AV11: 59.277873 | AW11: 29.335317 | AX11: 40.189655 | AY11: 80.614583 | AZ11: 29.401384 | BA11: 3.9034483 | BB11: 20.973214 | BC11: 7.2823741 | BD11: 34.753846 | BE11: 45.863248 | BF11: 37.938144
A12: 2 | B12: 35.797445 | C12: 29.44 | D12: 15.272727 | E12: 5.2888889 | F12: 17.577778 | G12: 5.5555556 | H12: 16.083491 | I12: 2.5646123 | J12: 36.534483 | K12: 77.810435 | L12: 33.022088 | M12: 29.251866 | N12: 12.318966 | O12: 48.798261 | P12: 12.027586 | Q12: 42.744828 | R12: 6.5149701 | S12: 31.724138 | T12: 69.080479 | U12: 31.82069 | V12: 8.6666667 | W12: 80.993007 | X12: 33.089494 | Y12: 43.423853 | Z12: 48.361423 | AA12: 33.723519 | AB12: 98.882353 | AC12: 1.0888889 | AD12: 7.8333333 | AE12: 14.656085 | AF12: 11.087444 | AG12: 6.742915 | AH12: 6.6865385 | AI12: 32.041379 | AJ12: 9.3368794 | AK12: 4.7428571 | AL12: 17.367003 | AM12: 12.926 | AN12: 15.251938 | AO12: 4.9168207 | AP12: 14.581315 | AQ12: 55.591304 | AR12: 4.0909091 | AS12: 27.719658 | AT12: 3.1834677 | AU12: 23.896104 | AV12: 69.891192 | AW12: 34.202925 | AX12: 46.672414 | AY12: 88.106346 | AZ12: 34.305699 | BA12: 4.3275862 | BB12: 28.63964 | BC12: 9.9140768 | BD12: 39.923208 | BE12: 52.555172 | BF12: 45.563478
A13: 2.25 | B13: 37.564748 | C13: 34.156306 | D13: 15.297297 | E13: 6.4 | F13: 21.044444 | G13: 6.4111111 | H13: 12.932331 | I13: 5.3941176 | J13: 44.233449 | K13: 95.142123 | L13: 36.876712 | M13: 29.83209 | N13: 14.377586 | O13: 60.571429 | P13: 14.165517 | Q13: 51.706897 | R13: 5.7485493 | S13: 36.917241 | T13: 76.941278 | U13: 36.859083 | V13: 10.740933 | W13: 97.344123 | X13: 35.393195 | Y13: 54.17033 | Z13: 56.755556 | AA13: 32.82971 | AB13: 113.98969 | AC13: 0.88888889 | AD13: 8.3388889 | AE13: 17.949153 | AF13: 12.713992 | AG13: 7.4057377 | AH13: 6.6889353 | AI13: 37.112069 | AJ13: 12.146617 | AK13: 4.3776091 | AL13: 17.875421 | AM13: 14.605749 | AN13: 18.474609 | AO13: 5.4463602 | AP13: 17.182906 | AQ13: 67.005236 | AR13: 2.2 | AS13: 31.976068 | AT13: 2.7357724 | AU13: 29.423598 | AV13: 81.864494 | AW13: 44.706226 | AX13: 53.925862 | AY13: 97.137931 | AZ13: 39.660959 | BA13: 5.5655172 | BB13: 45.128623 | BC13: 8.0253623 | BD13: 49.127846 | BE13: 60.614601 | BF13: 54.725557
A14: 2.5 | B14: 42.778169 | C14: 39.902827 | D14: 17.154696 | E14: 9.7777778 | F14: 21.077778 | G14: 6.0944444 | H14: 19.864646 | I14: 4.3855186 | J14: 54.121107 | K14: 102.12027 | L14: 48.028169 | M14: 35.929889 | N14: 15.331034 | O14: 67.429072 | P14: 17.165517 | Q14: 60.812069 | R14: 8.5705263 | S14: 42.172414 | T14: 83.010327 | U14: 43.205527 | V14: 13.956897 | W14: 108.69931 | X14: 40.885768 | Y14: 66.220401 | Z14: 70.005703 | AA14: 35.005338 | AB14: 120.88966 | AC14: 0.022222222 | AD14: 9.6111111 | AE14: 18.659459 | AF14: 15.325866 | AG14: 8.3913934 | AH14: 4.6912879 | AI14: 43.122414 | AJ14: 17.005525 | AK14: 6.4302103 | AL14: 17.975945 | AM14: 17.040307 | AN14: 19.678846 | AO14: 7.4572491 | AP14: 20.436742 | AQ14: 71.535284 | AR14: 3.36 | AS14: 35.615385 | AT14: 4.5445344 | AU14: 32.189394 | AV14: 94.913941 | AW14: 51.526718 | AX14: 63.155172 | AY14: 106.98267 | AZ14: 48.017182 | BA14: 9.5517241 | BB14: 55.560976 | BC14: 10.98895 | BD14: 60.720486 | BE14: 67.018868 | BF14: 64.425347
A15: 2.75 | B15: 45.580817 | C15: 44.033688 | D15: 18.698502 | E15: 12.805556 | F15: 21.266667 | G15: 6.4111111 | H15: 22.60404 | I15: 5.6737288 | J15: 63.153448 | K15: 107.45719 | L15: 51.774131 | M15: 36.396584 | N15: 16.22069 | O15: 73.4 | P15: 19.862069 | Q15: 70.532646 | R15: 10.206612 | S15: 46.917241 | T15: 89.60312 | U15: 49.578856 | V15: 16.496564 | W15: 117.57192 | X15: 50.847866 | Y15: 74.967568 | Z15: 80.192817 | AA15: 52.916814 | AB15: 127.56195 | AC15: 0.46666667 | AD15: 10.977778 | AE15: 19.961957 | AF15: 17.716102 | AG15: 9.2059925 | AH15: 4.6934866 | AI15: 48.482759 | AJ15: 16.318021 | AK15: 10.9 | AL15: 18.618151 | AM15: 18.193684 | AN15: 22.713761 | AO15: 7.2640145 | AP15: 23.324653 | AQ15: 76.759582 | AR15: 2.48 | AS15: 40.307692 | AT15: 4.6121212 | AU15: 37.774368 | AV15: 105.36649 | AW15: 57.667932 | AX15: 71.717241 | AY15: 116.33741 | AZ15: 55.070812 | BA15: 13.137931 | BB15: 56.470588 | BC15: 12.023211 | BD15: 71.498246 | BE15: 72.775128 | BF15: 72.892734
... A44: 10 | B44: 130.67156 | C44: 215.06061 | D44: 133.71786 | E44: 84.065217 | F44: 30.516129 | G44: 4.758427 | H44: 62.768763 | I44: 37.177914 | J44: 268.69983 | K44: 312.47676 | L44: 198.25331 | M44: 75.272897 | N44: 14.87931 | O44: 173.99655 | P44: 94.851724 | Q44: 267.20482 | R44: 62.027484 | S44: 220.46154 | T44: 316.5757 | U44: 279.92721 | V44: 78.034247 | W44: 411.79066 | X44: 254.71614 | Y44: 315.81329 | Z44: 314.22222 | AA44: 356.26619 | AB44: 280.16034 | AC44: 18.875 | AD44: 41.844444 | AE44: 41.239362 | AF44: 60.117172 | AG44: 23.302281 | AH44: 31.556701 | AI44: 193.53873 | AJ44: 95.524306 | AK44: 52.857671 | AL44: 163.30479 | AM44: 77.946392 | AN44: 128.12383 | AO44: 38.155039 | AP44: 136.74486 | AQ44: 190.97436 | AR44: 12.546392 | AS44: 179.94107 | AT44: 11.516129 | AU44: 143.61524 | AV44: 375.0829 | AW44: 296.52713 | AX44: 290.86356 | AY44: 313.1453 | AZ44: 286.92215 | BA44: 105.45061 | BB44: 280.30165 | BC44: 103.06654 | BD44: 421.43932 | BE44: 299.52721 | BF44: 310.88144

Sheet MCF10a-front
A1: Front data of All MCF10a samples (N=40)
B2: A3 | H2: B1 | K2: B2 | R2: B3 | AA2: C1 | AD2: C2 | AF2: C3 | AJ2: D1 | AL2: D2 | AN2: D3
A3: Time [h] | B3: Sample A | C3: Sample B | D3: Sample C | E3: Sample D | F3: Sample E | G3: Sample F | H3: Sample A | I3: Sample B | J3: Sample C | K3: Sample A | L3: Sample B | M3: Sample C | N3: Sample D | O3: Sample E | P3: Sample F | Q3: Sample G | R3: Sample A | S3: Sample B | T3: Sample C | U3: Sample D | V3: Sample E | W3: Sample F | X3: Sample G | Y3: Sample H | Z3: Sample I | AA3: Sample A | AB3: Sample B | AC3: Sample C | AD3: Sample A | AE3: Sample B | AF3: Sample A | AG3: Sample B | AH3: Sample C | AI3: Sample D | AJ3: Sample A | AK3: Sample B | AL3: Sample A | AM3: Sample B | AN3: Sample A | AO3: Sample B
A4: 0 | B4: 0 | C4: 0 | D4: 0 | E4: 0 | F4: 0 | G4: 0 | H4: 0 | I4: 0 | J4: 0 | K4: 0 | L4: 0 | M4: 0 | N4: 0 | O4: 0 | P4: 0 | Q4: 0 | R4: 0 | S4: 0 | T4: 0 | U4: 0 | V4: 0 | W4: 0 | X4: 0 | Y4: 0 | Z4: 0 | AA4: 0 | AB4: 0 | AC4: 0 | AD4: 0 | AE4: 0 | AF4: 0 | AG4: 0 | AH4: 0 | AI4: 0 | AJ4: 0 | AK4: 0 | AL4: 0 | AM4: 0 | AN4: 0 | AO4: 0
A5: 0.25 | B5: 7.3447099 | C5: 6.2495812 | D5: 7.0912162 | E5: 7.7516779 | F5: 6.5753425 | G5: 6.7959528 | H5: 3.875 | I5: 3.015625 | J5: 4.1368421 | K5: 5.1788756 | L5: 5.5819113 | M5: 4.791423 | N5: 8.9146758 | O5: 13.780687 | P5: 4.7959184 | Q5: 6.5344538 | R5: 5.2 | S5: 4.7996546 | T5: 3.9706422 | U5: 10.837456 | V5: 1.1523297 | W5: 13.15736 | X5: 4.3986371 | Y5: 6.1728188 | Z5: 7.020339 | AA5: 5.0744681 | AB5: 4.2934783 | AC5: 4.4322917 | AD5: 0.62056075 | AE5: 4.0067114 | AF5: 4.4364261 | AG5: 5.1241379 | AH5: 6.770903 | AI5: 7.1158433 | AJ5: 2.8547486 | AK5: 5.3958333 | AL5: 4.25 | AM5: 6.1927711 | AN5: 2.6943396 | AO5: 0.94
A6: 0.5 | B6: 14.040747 | C6: 12.097973 | D6: 13.59215 | E6: 14.996667 | F6: 12.722973 | G6: 12.805461 | H6: 7.4338624 | I6: 5.5555556 | J6: 7.5284974 | K6: 9.6903553 | L6: 10.708475 | M6: 12.679834 | N6: 17.222034 | O6: 17.137153 | P6: 8.9762309 | Q6: 12.445969 | R6: 10.045226 | S6: 9.0549828 | T6: 12.330224 | U6: 19.790493 | V6: 0.061946903 | W6: 8.6901173 | X6: 8.2675585 | Y6: 11.667774 | Z6: 13.64527 | AA6: 9.2903226 | AB6: 8.0691489 | AC6: 8.4974093 | AD6: 8.8365554 | AE6: 7.2847458 | AF6: 8.1327586 | AG6: 9.8982759 | AH6: 12.890017 | AI6: 13.636672 | AJ6: 5.0842105 | AK6: 11.095745 | AL6: 8 | AM6: 11.730508 | AN6: 15.857143 | AO6: 10.85687
A7: 0.75 | B7: 20.695205 | C7: 18.245791 | D7: 20.269036 | E7: 22.362098 | F7: 19.210169 | G7: 19.424448 | H7: 11.428571 | I7: 7.8125 | J7: 11.259259 | K7: 14.410866 | L7: 16.051195 | M7: 5.7186858 | N7: 26.107877 | O7: 21.974865 | P7: 13.398981 | Q7: 18.438031 | R7: 14.818951 | S7: 13.456998 | T7: 18.205078 | U7: 24.718464 | V7: 4.4691358 | W7: 12.141818 | X7: 12.438983 | Y7: 17.343333 | Z7: 20.260135 | AA7: 13.775401 | AB7: 12.120219 | AC7: 12.136842 | AD7: 6.3597122 | AE7: 10.734007 | AF7: 12.208547 | AG7: 14.786441 | AH7: 19.175676 | AI7: 20.591973 | AJ7: 7.65 | AK7: 16.906593 | AL7: 11.85034 | AM7: 16.889655 | AN7: 16.370445 | AO7: 9.33
A8: 1 | B8: 27.551959 | C8: 24.722789 | D8: 26.928934 | E8: 29.587838 | F8: 25.637437 | G8: 25.491611 | H8: 15.005291 | I8: 10.635897 | J8: 15.010363 | K8: 18.91443 | L8: 21.337248 | M8: 9.8314394 | N8: 34.934708 | O8: 28.030142 | P8: 17.715736 | Q8: 24.441026 | R8: 19.835034 | S8: 17.674099 | T8: 17.126819 | U8: 28.030466 | V8: 8.4283088 | W8: 22.450467 | X8: 16.384486 | Y8: 23.031987 | Z8: 26.742373 | AA8: 18.179487 | AB8: 16.455959 | AC8: 16.267677 | AD8: 20.338983 | AE8: 14.055838 | AF8: 15.960276 | AG8: 19.364407 | AH8: 25.29223 | AI8: 27.283784 | AJ8: 10.071038 | AK8: 23.212291 | AL8: 15.455479 | AM8: 21.963918 | AN8: 17.145251 | AO8: 11.499069
A9: 1.25 | B9: 34.18569 | C9: 31.243655 | D9: 33.522034 | E9: 36.957841 | F9: 32.602716 | G9: 32.036021 | H9: 18.677249 | I9: 13.243386 | J9: 18.87766 | K9: 23.431973 | L9: 26.574324 | M9: 14.57757 | N9: 43.643952 | O9: 36.652727 | P9: 22.090604 | Q9: 30.572881 | R9: 24.812709 | S9: 21.862779 | T9: 20.160966 | U9: 31.624101 | V9: 15.577132 | W9: 21.279264 | X9: 20.459732 | Y9: 28.453177 | Z9: 33.284983 | AA9: 23.020305 | AB9: 20.298969 | AC9: 20.365979 | AD9: 28.560579 | AE9: 17.490756 | AF9: 19.831919 | AG9: 24.132203 | AH9: 31.580645 | AI9: 34.149079 | AJ9: 12.281915 | AK9: 29.453039 | AL9: 19.121993 | AM9: 26.623264 | AN9: 18.930754 | AO9: 8.701275
A10: 1.5 | B10: 40.860825 | C10: 38.225 | D10: 40.295302 | E10: 44.276949 | F10: 39.619211 | G10: 38.413445 | H10: 22.42328 | I10: 15.579487 | J10: 22.196809 | K10: 27.935593 | L10: 32.023569 | M10: 18.427466 | N10: 52.098139 | O10: 42.896679 | P10: 26.450253 | Q10: 36.722317 | R10: 30.216582 | S10: 26.222603 | T10: 30.600849 | U10: 51.377609 | V10: 17.12616 | W10: 31.811847 | X10: 24.627319 | Y10: 34.023179 | Z10: 39.993266 | AA10: 26.91623 | AB10: 24.582888 | AC10: 24.420513 | AD10: 31.996324 | AE10: 20.881557 | AF10: 23.410562 | AG10: 28.745763 | AH10: 37.954545 | AI10: 40.94247 | AJ10: 14.926966 | AK10: 35.957672 | AL10: 22.63167 | AM10: 31.29432 | AN10: 22.232176 | AO10: 10.784722
A11: 1.75 | B11: 47.561644 | C11: 45.855442 | D11: 47.054422 | E11: 51.918919 | F11: 46.768581 | G11: 44.80067 | H11: 26.068783 | I11: 17.097297 | J11: 26.085561 | K11: 32.39629 | L11: 37.284512 | M11: 19.210526 | N11: 60.317949 | O11: 48.134831 | P11: 30.844974 | Q11: 42.962521 | R11: 35.541596 | S11: 30.540171 | T11: 32.112186 | U11: 64.630691 | V11: 30.83705 | W11: 26.681901 | X11: 28.792642 | Y11: 39.998328 | Z11: 46.648739 | AA11: 31.690722 | AB11: 29.276596 | AC11: 29.046154 | AD11: 35.922939 | AE11: 24.240803 | AF11: 27.294521 | AG11: 33.317241 | AH11: 44.482234 | AI11: 47.972973 | AJ11: 17.52809 | AK11: 42.739362 | AL11: 26.55137 | AM11: 35.699825 | AN11: 29.623188 | AO11: 24.726882
A12: 2 | B12: 54.269165 | C12: 53.426891 | D12: 53.809764 | E12: 59.451827 | F12: 54.486301 | G12: 51.588832 | H12: 29.834171 | I12: 19.816216 | J12: 29.940217 | K12: 36.858108 | L12: 42.519525 | M12: 22.372917 | N12: 68.900515 | O12: 57.116928 | P12: 35.464527 | Q12: 49.269297 | R12: 40.923986 | S12: 34.964346 | T12: 41.099576 | U12: 61.921603 | V12: 26.233663 | W12: 28.251376 | X12: 32.911565 | Y12: 45.34106 | Z12: 53.056218 | AA12: 36.026178 | AB12: 33.273196 | AC12: 33.709677 | AD12: 49.487847 | AE12: 27.722973 | AF12: 31.127986 | AG12: 37.960345 | AH12: 51.153199 | AI12: 54.762309 | AJ12: 19.816667 | AK12: 49.241758 | AL12: 30.227656 | AM12: 40.161512 | AN12: 37.39212 | AO12: 24.644711
A13: 2.25 | B13: 61.798969 | C13: 62.728499 | D13: 61.547458 | E13: 67.882155 | F13: 63.678082 | G13: 59.267797 | H13: 34.467337 | I13: 22.738462 | J13: 34.68254 | K13: 42.560606 | L13: 48.894737 | M13: 21.073864 | N13: 78.855918 | O13: 56.344464 | P13: 40.826758 | Q13: 56.670608 | R13: 47.705281 | S13: 39.778157 | T13: 43.928279 | U13: 74.092749 | V13: 24.806569 | W13: 46.758389 | X13: 38.379019 | Y13: 52.247508 | Z13: 60.323232 | AA13: 41.746114 | AB13: 39.005319 | AC13: 39.251337 | AD13: 39.814471 | AE13: 32.033557 | AF13: 36.235495 | AG13: 43.537931 | AH13: 59.123103 | AI13: 62.662116 | AJ13: 23.435028 | AK13: 57.308989 | AL13: 35.030875 | AM13: 45.367067 | AN13: 38.63472 | AO13: 22.128571
A14: 2.5 | B14: 69.499154 | C14: 70.118644 | D14: 69.409091 | E14: 74.459098 | F14: 68.719864 | G14: 66.530822 | H14: 41.668342 | I14: 29.297297 | J14: 37.104167 | K14: 49.736041 | L14: 53.219015 | M14: 23.106542 | N14: 86.409168 | O14: 63.478261 | P14: 47.337931 | Q14: 61.616949 | R14: 56.479592 | S14: 44.098976 | T14: 51.513158 | U14: 83.210526 | V14: 32.471058 | W14: 43.913121 | X14: 45.114478 | Y14: 60.332215 | Z14: 67.670085 | AA14: 44.588542 | AB14: 43.191489 | AC14: 43.43299 | AD14: 44.818027 | AE14: 38.425676 | AF14: 44.48731 | AG14: 50.267797 | AH14: 67.180602 | AI14: 69.665529 | AJ14: 26.816216 | AK14: 61.792746 | AL14: 41.497427 | AM14: 50.243056 | AN14: 47.913295 | AO14: 34.826087
A15: 2.75 | B15: 76.802721 | C15: 76.910473 | D15: 76.295726 | E15: 80.507513 | F15: 73.284014 | G15: 72.768439 | H15: 48.316583 | I15: 35.103093 | J15: 39.507772 | K15: 56.204429 | L15: 56.852792 | M15: 23.604124 | N15: 92.80789 | O15: 76.245217 | P15: 53.103093 | Q15: 66.211864 | R15: 64.541039 | S15: 48.006814 | T15: 41.851852 | U15: 82.710432 | V15: 41.782374 | W15: 46.488095 | X15: 51.907407 | Y15: 67.245 | Z15: 74.373083 | AA15: 47.060606 | AB15: 47.725806 | AC15: 47.497462 | AD15: 45.893939 | AE15: 44.159052 | AF15: 51.760943 | AG15: 56.233898 | AH15: 74.4701 | AI15: 76.470187 | AJ15: 28.867403 | AK15: 66.198953 | AL15: 47.611486 | AM15: 55.226576 | AN15: 65.037997 | AO15: 36.530488
... A32: 7 | B32: 204.69088 | C32: 183.99144 | D32: 194.15333 | E32: 184.72483 | F32: 161.70578 | G32: 175.0781 | H32: 116.24742 | I32: 100.10256 | J32: 78.705263 | K32: 185.04216 | L32: 127.0735 | M32: 72.667917 | N32: 195.4481 | O32: 206.05217 | P32: 155.01005 | Q32: 153.39763 | R32: 184.95262 | S32: 131.20812 | T32: 127.82941 | U32: 209.35225 | V32: 139.33272 | W32: 165.29159 | X32: 172.2326 | Y32: 174.4 | Z32: 213.94378 | AA32: 75.221622 | AB32: 103.68783 | AC32: 118.84153 | AD32: 176.39719 | AE32: 154.86125 | AF32: 167.63808 | AG32: 180.59322 | AH32: 217.12646 | AI32: 198.65878 | AJ32: 30.026596 | AK32: 136.16667 | AL32: 157.56775 | AM32: 139.10051 | AN32: 210.04745 | AO32: 95.771267
A33: 7.25 | B33: 214.7449 | C33: 191.9797 | D33: 201.72927 | E33: 192.0183 | F33: 168.73595 | G33: 181.22712 | H33: 118.65979 | I33: 102.87179 | J33: 82.687831 | K33: 193.91216 | L33: 133.61889 | M33: 67.54195 | N33: 201.53925 | O33: 214.87395 | P33: 161.247 | Q33: 158.91952 | R33: 192.57939 | S33: 137.58662 | T33: 136.22833 | U33: 216.71356 | V33: 159.14488 | W33: 174.38791 | X33: 179.93878 | Y33: 181.94128 | Z33: 225.4837 | AA33: 77.457447 | AB33: 108.16754 | AC33: 125.64286 | AD33: 196.05584 | AE33: 163.14552 | AF33: 176.02385 | AG33: 189.35932 | AH33: 230.12228 | AI33: 208.64576 | AJ33: 26.49162 | AK33: NaN | AL33: 165.2226 | AM33: 142.49488 | AN33: 220.33725 | AO33: 101.76909
A34: 7.5 | B34: 222.00345 | C34: 199.11506 | D34: 208.35304 | E34: 200.80602 | F34: 175.09655 | G34: 191.34932 | H34: 121.69898 | I34: 103.78378 | J34: 88.302083 | K34: 203.8322 | L34: 136.41554 | M34: 70.251418 | N34: 210.78007 | O34: 230.19217 | P34: 168.89831 | Q34: 164.59098 | R34: 202.35025 | S34: 145.39249 | T34: 149.42344 | U34: 221.62082 | V34: 167.1943 | W34: 180.54266 | X34: 189.81218 | Y34: 189.69767 | Z34: 234.44804 | AA34: 80.071066 | AB34: 106.21164 | AC34: 128.49735 | AD34: 192.63636 | AE34: 170.4605 | AF34: 183.50258 | AG34: 198.42513 | AH34: 239.15385 | AI34: 217.90186 | AJ34: 25.303191 | AK34: NaN | AL34: 174.48542 | AM34: 148.92427 | AN34: 226.49524 | AO34: 107.04
A35: 7.75 | B35: 228.66159 | C35: 206.45854 | D35: 215.32264 | E35: 208.63497 | F35: 180.58591 | G35: 200.8769 | H35: 124.57286 | I35: 105.6 | J35: 93.247253 | K35: 213.32363 | L35: 138.8125 | M35: 72.657371 | N35: 219.68034 | O35: 236.40283 | P35: 176.02525 | Q35: 169.10526 | R35: 211.59831 | S35: 152.60307 | T35: 155.72587 | U35: 228.41509 | V35: 174.1182 | W35: 186.48352 | X35: 197.59259 | Y35: 197.18289 | Z35: 241.99831 | AA35: 80.13369 | AB35: 106.69355 | AC35: 128.61026 | AD35: 219.52364 | AE35: 177.38842 | AF35: 189.55707 | AG35: 207.69844 | AH35: 246.58844 | AI35: 226.14334 | AJ35: 22.772727 | AK35: NaN | AL35: 183.7307 | AM35: 154.56304 | AN35: 241.95856 | AO35: 110.146
A36: 8 | B36: 234.70798 | C36: 212.09122 | D36: 222.09814 | E36: 217.32943 | F36: 186.54252 | G36: 210.48475 | H36: 127.79058 | I36: 108.08649 | J36: 98.104396 | K36: 222.94746 | L36: 141.40986 | M36: 73.49697 | N36: 228.11592 | O36: 237.62888 | P36: 182.98988 | Q36: 174.32203 | R36: 220.25424 | S36: 159.76988 | T36: 151.42355 | U36: 234.03377 | V36: 177.24329 | W36: 196.96911 | X36: 206.34126 | Y36: 204.49747 | Z36: 249.17785 | AA36: 82.868687 | AB36: 105.97849 | AC36: 129.41117 | AD36: 205.24466 | AE36: 184.20903 | AF36: 196.35374 | AG36: 216.43419 | AH36: 252.90756 | AI36: 234.28739 | AJ36: 20.393258 | AK36: NaN | AL36: 193.01012 | AM36: 160.46678 | AN36: 248.4636 | AO36: 114.89555
A37: 8.25 | B37: 240.63652 | C37: 219.78511 | D37: 228.87879 | E37: 225.29442 | F37: 192.33103 | G37: 220.1489 | H37: 131.0404 | I37: 110.12821 | J37: 103.27473 | K37: 232.98151 | L37: 144.45973 | M37: 81.929078 | N37: 237.0223 | O37: 251.58497 | P37: 190.11565 | Q37: 179.21489 | R37: 229.55833 | S37: 166.64888 | T37: 154.9896 | U37: 245.3113 | V37: 160.22043 | W37: 201.65918 | X37: 214.81678 | Y37: 212.39698 | Z37: 256.62437 | AA37: 85.372449 | AB37: 104.31694 | AC37: 132.15707 | AD37: 210.43407 | AE37: 190.51007 | AF37: 202.9063 | AG37: 225.95563 | AH37: 259.10368 | AI37: 243.4 | AJ37: 18.894444 | AK37: NaN | AL37: 201.91379 | AM37: 166.32582 | AN37: 261.15244 | AO37: 109.93774
A38: 8.5 | B38: 246.35264 | C38: 224.95601 | D38: 235.72697 | E38: 233.58923 | F38: 197.86007 | G38: 229.52782 | H38: 134.20408 | I38: 111.5641 | J38: 107.9011 | K38: 242.73162 | L38: 146.61017 | M38: 80.312127 | N38: 245.42042 | O38: 256.48713 | P38: 197.28351 | Q38: 183.57705 | R38: 238.565 | S38: 173.51291 | T38: 167.84038 | U38: 250.95238 | V38: 191.09786 | W38: 227.15925 | X38: 222.67572 | Y38: 219.46333 | Z38: 264.1395 | AA38: 85.835897 | AB38: 103.13369 | AC38: 132.58602 | AD38: 232.32399 | AE38: 197.33611 | AF38: 209.7225 | AG38: 236.18621 | AH38: 264.43072 | AI38: 252.42275 | AJ38: 16.015873 | AK38: NaN | AL38: 210.96082 | AM38: 172.64116 | AN38: 255.05233 | AO38: 125.03239
A39: 8.75 | B39: 251.79828 | C39: 231.67005 | D39: 242.70068 | E39: 241.99493 | F39: 203.98639 | G39: 239.19355 | H39: 137.60963 | I39: 113.43784 | J39: 109.67188 | K39: 252.69529 | L39: 148.88946 | M39: 83.324324 | N39: 254.13621 | O39: 261.37205 | P39: 204.48537 | Q39: 188.76102 | R39: 247.43151 | S39: 180.33391 | T39: 161.5251 | U39: 256.34435 | V39: 205.59266 | W39: 230.83759 | X39: 231.05622 | Y39: 226.63149 | Z39: 271.58097 | AA39: 87.544041 | AB39: 101.91623 | AC39: 135.15789 | AD39: 244.2535 | AE39: 204.12014 | AF39: 216.13729 | AG39: 245.85986 | AH39: 269.96494 | AI39: 261.83051 | AJ39: 9.8235294 | AK39: NaN | AL39: 220.18259 | AM39: 178.66207 | AN39: 277.62035 | AO39: 122.85065
A40: 9 | B40: 257.91282 | C40: 237.86248 | D40: 249.48485 | E40: 250.57311 | F40: 210.494 | G40: 248.80207 | H40: 142.74627 | I40: 115.13846 | J40: 110.26842 | K40: 262.89358 | L40: 151.86294 | M40: 88.443262 | N40: 263.02901 | O40: 272.07641 | P40: 212.46102 | Q40: 193.93243 | R40: 256.36364 | S40: 187.2599 | T40: 172.85714 | U40: 271.80929 | V40: 200.47458 | W40: 240.2775 | X40: 239.47466 | Y40: 234.27919 | Z40: 278.11356 | AA40: 88.421875 | AB40: 102.08763 | AC40: 134.85792 | AD40: 248.96964 | AE40: 210.85329 | AF40: 223.28669 | AG40: 255.86565 | AH40: 274.82968 | AI40: 271.36931 | AJ40: 9.8540541 | AK40: NaN | AL40: 229.25127 | AM40: 184.95238 | AN40: 279.98305 | AO40: 131.65356
A41: 9.25 | B41: 263.45533 | C41: 245.08844 | D41: 256.69661 | E41: 258.72835 | F41: 216.53242 | G41: 258.19761 | H41: 146.73096 | I41: 116.78462 | J41: 98.010695 | K41: 272.71933 | L41: 154.89244 | M41: 93.082061 | N41: 271.60239 | O41: 274.34107 | P41: 220.16808 | Q41: 199.05705 | R41: 265.17953 | S41: 194.01033 | T41: 174.68868 | U41: 275.6 | V41: 185.68717 | W41: 253.25641 | X41: 247.63697 | Y41: 241.70389 | Z41: 285.78451 | AA41: 92.086294 | AB41: 101.86458 | AC41: 135.15464 | AD41: 264.46564 | AE41: 217.73445 | AF41: 230.92295 | AG41: 266.47521 | AH41: 279.12437 | AI41: 282.3887 | AJ41: 6.5185185 | AK41: NaN | AL41: 238.36473 | AM41: 191.24658 | AN41: 286.78085 | AO41: 135.59006
A42: 9.5 | B42: 269.84148 | C42: 251.65042 | D42: 263.63866 | E42: 266.97651 | F42: 222.99489 | G42: 267.08938 | H42: 151.27957 | I42: 119.10256 | J42: 47.410526 | K42: 283.06061 | L42: 157.42282 | M42: 98.106061 | N42: 280.2906 | O42: 287.20725 | P42: 228.1387 | Q42: 203.02906 | R42: 273.50256 | S42: 201.1912 | T42: 176.23855 | U42: 283.14834 | V42: 234.34058 | W42: 246.24013 | X42: 255.93515 | Y42: 249.15567 | Z42: 292.71501 | AA42: 94.258706 | AB42: 100.64835 | AC42: 136.10995 | AD42: 266.54844 | AE42: 224.38151 | AF42: 239.24704 | AG42: 276.74915 | AH42: 282.03673 | AI42: 292.78246 | AJ42: 5.5751295 | AK42: NaN | AL42: 247.53288 | AM42: 197.84682 | AN42: 290.19578 | AO42: 143.28773
A43: 9.75 | B43: 276.12415 | C43: 259.63185 | D43: 271.67953 | E43: 277.06868 | F43: 229.45868 | G43: 277.0034 | H43: 159.28351 | I43: 122.06154 | J43: 72.180328 | K43: 294.67808 | L43: 161.38514 | M43: 93.604743 | N43: 289.81834 | O43: 297.91348 | P43: 237.51771 | Q43: 208.8613 | R43: 282.93929 | S43: 208.91709 | T43: 187.80755 | U43: 297.87587 | V43: 213.97464 | W43: 243.98587 | X43: 265.39798 | Y43: 257.23012 | Z43: 300.90017 | AA43: 96.820106 | AB43: 100.58919 | AC43: 138.875 | AD43: 288.16201 | AE43: 232.13591 | AF43: 248.4276 | AG43: 289.8887 | AH43: 289.6505 | AI43: 305.59322 | AJ43: 17.171123 | AK43: NaN | AL43: 257.15043 | AM43: 205.68889 | AN43: 288.23709 | AO43: 148.61456
